<?xml version="1.0" ?>
<robot name="lbr_iiwa_with_wsg50">
  <material name="Black">
    <color rgba="0.2 0.2 0.2 1.0"/>
  </material>
  <material name="Grey">
    <color rgba="0.5 0.5 0.5 1.0"/>
  </material>
  <material name="Orange">
    <color rgba="1.0 0.423529411765 0.0392156862745 1.0"/>
  </material>
  <material name="Blue">
    <color rgba="0.5 0.7 1.0 1.0"/>
  </material>

  <joint name="lbr_iiwa_with_wsg50__J0" type="revolute">
    <parent link="lbr_iiwa_with_wsg50__lbr_iiwa_link_0"/>
    <child link="lbr_iiwa_with_wsg50__lbr_iiwa_link_1"/>
    <origin rpy="0  0  0" xyz="0      0.0      0.1575"/>
    <axis xyz="0  0  1"/>
    <limit effort="300.0" lower="-2.96706" upper="2.96706" velocity="10.0"/>
  </joint>
  <joint name="lbr_iiwa_with_wsg50__J1" type="revolute">
    <parent link="lbr_iiwa_with_wsg50__lbr_iiwa_link_1"/>
    <child link="lbr_iiwa_with_wsg50__lbr_iiwa_link_2"/>
    <origin rpy="1.5708   0      -3.14159" xyz="0      0      0.2025"/>
    <axis xyz="0  0  1"/>
    <limit effort="300.0" lower="-2.0944" upper="2.0944" velocity="10.0"/>
  </joint>
  <joint name="lbr_iiwa_with_wsg50__J2" type="revolute">
    <parent link="lbr_iiwa_with_wsg50__lbr_iiwa_link_2"/>
    <child link="lbr_iiwa_with_wsg50__lbr_iiwa_link_3"/>
    <origin rpy="1.5708   0      -3.14159" xyz="0      0.2045  0"/>
    <axis xyz="0  0  1"/>
    <limit effort="300.0" lower="-2.96706" upper="2.96706" velocity="10.0"/>
  </joint>
  <joint name="lbr_iiwa_with_wsg50__J3" type="revolute">
    <parent link="lbr_iiwa_with_wsg50__lbr_iiwa_link_3"/>
    <child link="lbr_iiwa_with_wsg50__lbr_iiwa_link_4"/>
    <origin rpy="1.5708  0      0" xyz="0      0      0.2155"/>
    <axis xyz="0  0  1"/>
    <limit effort="300.0" lower="-2.0944" upper="2.0944" velocity="10.0"/>
  </joint>
  <joint name="lbr_iiwa_with_wsg50__J4" type="revolute">
    <parent link="lbr_iiwa_with_wsg50__lbr_iiwa_link_4"/>
    <child link="lbr_iiwa_with_wsg50__lbr_iiwa_link_5"/>
    <origin rpy="1.5708   0       3.14159" xyz="0      0.1845  0"/>
    <axis xyz="0  0  1"/>
    <limit effort="300.0" lower="-2.96706" upper="2.96706" velocity="10.0"/>
  </joint>
  <joint name="lbr_iiwa_with_wsg50__J5" type="revolute">
    <parent link="lbr_iiwa_with_wsg50__lbr_iiwa_link_5"/>
    <child link="lbr_iiwa_with_wsg50__lbr_iiwa_link_6"/>
    <origin rpy="1.5708  0      0" xyz="0      0      0.2155"/>
    <axis xyz="0  0  1"/>
    <limit effort="300.0" lower="-2.0944" upper="2.0944" velocity="10.0"/>
  </joint>
  <joint name="lbr_iiwa_with_wsg50__J6" type="revolute">
    <parent link="lbr_iiwa_with_wsg50__lbr_iiwa_link_6"/>
    <child link="lbr_iiwa_with_wsg50__lbr_iiwa_link_7"/>
    <origin rpy="1.5708   0      -3.14159" xyz="0     0.081  0"/>
    <axis xyz="0  0  1"/>
    <limit effort="300.0" lower="-3.05433" upper="3.05433" velocity="10.0"/>
  </joint>
  <joint name="lbr_iiwa_with_wsg50__gripper_to_arm" type="continuous">
    <parent link="lbr_iiwa_with_wsg50__lbr_iiwa_link_7"/>
    <child link="lbr_iiwa_with_wsg50__base_link"/>
    <origin rpy="0  0  0" xyz="0     0     0.044"/>
    <axis xyz="0  0  1"/>
    <limit effort="0" lower="0" upper="0" velocity="0"/>
  </joint>
  <joint name="lbr_iiwa_with_wsg50__base_left_finger_joint" type="revolute">
    <parent link="lbr_iiwa_with_wsg50__base_link"/>
    <child link="lbr_iiwa_with_wsg50__left_finger"/>
    <origin rpy="0   -0.05  0" xyz="0     0.024  0.045"/>
    <axis xyz="0  1  0"/>
    <limit effort="100.0" lower="-10.4" upper="10.01" velocity="0.0"/>
  </joint>
  <joint name="lbr_iiwa_with_wsg50__left_finger_base_joint" type="fixed">
    <parent link="lbr_iiwa_with_wsg50__left_finger"/>
    <child link="lbr_iiwa_with_wsg50__left_finger_base"/>
    <origin rpy="0   -0.25  0" xyz="-0.00099  0       0.08015"/>
    <axis xyz="0  0  0"/>
    <limit effort="0" lower="0" upper="0" velocity="0"/>
  </joint>
  <joint name="lbr_iiwa_with_wsg50__left_base_tip_joint" type="revolute">
    <parent link="lbr_iiwa_with_wsg50__left_finger_base"/>
    <child link="lbr_iiwa_with_wsg50__left_finger_tip"/>
    <origin rpy="0   0.5  0" xyz="0.0034   0       0.06175"/>
    <axis xyz="0  1  0"/>
    <limit effort="0.0" lower="-10.1" upper="10.3" velocity="0.0"/>
  </joint>
  <joint name="lbr_iiwa_with_wsg50__base_right_finger_joint" type="revolute">
    <parent link="lbr_iiwa_with_wsg50__base_link"/>
    <child link="lbr_iiwa_with_wsg50__right_finger"/>
    <origin rpy="0    0.05  0" xyz="0     0.024  0.045"/>
    <axis xyz="0  1  0"/>
    <limit effort="100.0" lower="-10.01" upper="10.4" velocity="0.0"/>
  </joint>
  <joint name="lbr_iiwa_with_wsg50__right_finger_base_joint" type="fixed">
    <parent link="lbr_iiwa_with_wsg50__right_finger"/>
    <child link="lbr_iiwa_with_wsg50__right_finger_base"/>
    <origin rpy="0    0.25  0" xyz="0.00099  0       0.08015"/>
    <axis xyz="0  0  0"/>
    <limit effort="0" lower="0" upper="0" velocity="0"/>
  </joint>
  <joint name="lbr_iiwa_with_wsg50__right_base_tip_joint" type="revolute">
    <parent link="lbr_iiwa_with_wsg50__right_finger_base"/>
    <child link="lbr_iiwa_with_wsg50__right_finger_tip"/>
    <origin rpy="0  -0.5  0" xyz="-0.0034   0       0.06175"/>
    <axis xyz="0  1  0"/>
    <limit effort="0.0" lower="-10.3" upper="10.1" velocity="0.0"/>
  </joint>
  <link name="lbr_iiwa_with_wsg50__lbr_iiwa_link_0">
    <inertial>
      <mass value="0"/>
      <origin rpy="0  0  0" xyz="0.0   0    0.07"/>
      <inertia ixx="0.05" ixy="0" ixz="0" iyy="0.06" iyz="0" izz="0.03"/>
    </inertial>
    <collision name="lbr_iiwa_with_wsg50__lbr_iiwa_link_0_collision">
      <origin rpy="0  0  0" xyz="0  0  0"/>
      <geometry>
        <mesh filename="meshes/link_0.stl" scale="1 1 1"/>
      </geometry>
    </collision>
    <visual name="lbr_iiwa_with_wsg50__lbr_iiwa_link_0_visual">
      <origin rpy="0  0  0" xyz="0  0  0"/>
      <geometry>
        <mesh filename="meshes/link_0.stl" scale="1 1 1"/>
      </geometry>
      <material name="Black" />
    </visual>
  </link>
  <link name="lbr_iiwa_with_wsg50__lbr_iiwa_link_1">
    <inertial>
      <mass value="4"/>
      <origin rpy="0  0  0" xyz="0   -0.03  0.12"/>
      <inertia ixx="0.1" ixy="0" ixz="0" iyy="0.09" iyz="0" izz="0.02"/>
    </inertial>
    <collision name="lbr_iiwa_with_wsg50__lbr_iiwa_link_1_collision">
      <origin rpy="0  0  0" xyz="0  0  0"/>
      <geometry>
        <mesh filename="meshes/link_1.stl" scale="1 1 1"/>
      </geometry>
    </collision>
    <visual name="lbr_iiwa_with_wsg50__lbr_iiwa_link_1_visual">
      <origin rpy="0  0  0" xyz="0  0  0"/>
      <geometry>
        <mesh filename="meshes/link_1.stl" scale="1 1 1"/>
      </geometry>
      <material name="Blue" />
    </visual>
  </link>
  <link name="lbr_iiwa_with_wsg50__lbr_iiwa_link_2">
    <inertial>
      <mass value="4"/>
      <origin rpy="0  0  0" xyz="0.00029  0.059    0.042"/>
      <inertia ixx="0.05" ixy="0" ixz="0" iyy="0.018" iyz="0" izz="0.044"/>
    </inertial>
    <collision name="lbr_iiwa_with_wsg50__lbr_iiwa_link_2_collision">
      <origin rpy="0  0  0" xyz="0  0  0"/>
      <geometry>
        <mesh filename="meshes/link_2.stl" scale="1 1 1"/>
      </geometry>
    </collision>
    <visual name="lbr_iiwa_with_wsg50__lbr_iiwa_link_2_visual">
      <origin rpy="0  0  0" xyz="0  0  0"/>
      <geometry>
        <mesh filename="meshes/link_2.stl" scale="1 1 1"/>
      </geometry>
      <material name="Blue"/>
    </visual>
  </link>
  <link name="lbr_iiwa_with_wsg50__lbr_iiwa_link_3">
    <inertial>
      <mass value="3"/>
      <origin rpy="0  0  0" xyz="0    0.03  0.13"/>
      <inertia ixx="0.08" ixy="0" ixz="0" iyy="0.075" iyz="0" izz="0.01"/>
    </inertial>
    <collision name="lbr_iiwa_with_wsg50__lbr_iiwa_link_3_collision">
      <origin rpy="0  0  0" xyz="0  0  0"/>
      <geometry>
        <mesh filename="meshes/link_3.stl" scale="1 1 1"/>
      </geometry>
    </collision>
    <visual name="lbr_iiwa_with_wsg50__lbr_iiwa_link_3_visual">
      <origin rpy="0  0  0" xyz="0  0  0"/>
      <geometry>
        <mesh filename="meshes/link_3.stl" scale="1 1 1"/>
      </geometry>
      <material name="Blue"/>
    </visual>
  </link>
  <link name="lbr_iiwa_with_wsg50__lbr_iiwa_link_4">
    <inertial>
      <mass value="2.7"/>
      <origin rpy="0  0  0" xyz="0     0.067  0.034"/>
      <inertia ixx="0.03" ixy="0" ixz="0" iyy="0.01" iyz="0" izz="0.029"/>
    </inertial>
    <collision name="lbr_iiwa_with_wsg50__lbr_iiwa_link_4_collision">
      <origin rpy="0  0  0" xyz="0  0  0"/>
      <geometry>
        <mesh filename="meshes/link_4.stl" scale="1 1 1"/>
      </geometry>
    </collision>
    <visual name="lbr_iiwa_with_wsg50__lbr_iiwa_link_4_visual">
      <origin rpy="0  0  0" xyz="0  0  0"/>
      <geometry>
        <mesh filename="meshes/link_4.stl" scale="1 1 1"/>
      </geometry>
      <material name="Orange"/>
    </visual>
  </link>
  <link name="lbr_iiwa_with_wsg50__lbr_iiwa_link_5">
    <inertial>
      <mass value="1.7"/>
      <origin rpy="0  0  0" xyz="0.0001  0.021   0.076"/>
      <inertia ixx="0.02" ixy="0" ixz="0" iyy="0.018" iyz="0" izz="0.005"/>
    </inertial>
    <collision name="lbr_iiwa_with_wsg50__lbr_iiwa_link_5_collision">
      <origin rpy="0  0  0" xyz="0  0  0"/>
      <geometry>
        <mesh filename="meshes/link_5.stl" scale="1 1 1"/>
      </geometry>
    </collision>
    <visual name="lbr_iiwa_with_wsg50__lbr_iiwa_link_5_visual">
      <origin rpy="0  0  0" xyz="0  0  0"/>
      <geometry>
        <mesh filename="meshes/link_5.stl" scale="1 1 1"/>
      </geometry>
      <material name="Blue" />
    </visual>
  </link>
  <link name="lbr_iiwa_with_wsg50__lbr_iiwa_link_6">
    <inertial>
      <mass value="1.8"/>
      <origin rpy="0  0  0" xyz="0       0.00059  0.0004"/>
      <inertia ixx="0.005" ixy="0" ixz="0" iyy="0.0036" iyz="0" izz="0.0047"/>
    </inertial>
    <collision name="lbr_iiwa_with_wsg50__lbr_iiwa_link_6_collision">
      <origin rpy="0  0  0" xyz="0  0  0"/>
      <geometry>
        <mesh filename="meshes/link_6.stl" scale="1 1 1"/>
      </geometry>
    </collision>
    <visual name="lbr_iiwa_with_wsg50__lbr_iiwa_link_6_visual">
      <origin rpy="0  0  0" xyz="0  0  0"/>
      <geometry>
        <mesh filename="meshes/link_6.stl" scale="1 1 1"/>
      </geometry>
      <material name="Orange"/>
    </visual>
  </link>
  <link name="lbr_iiwa_with_wsg50__lbr_iiwa_link_7">
    <inertial>
      <mass value="1.3"/>
      <origin rpy="0  0  0" xyz="0    0    0.02"/>
      <inertia ixx="0.001" ixy="0" ixz="0" iyy="0.001" iyz="0" izz="0.001"/>
    </inertial>
    <collision name="lbr_iiwa_with_wsg50__lbr_iiwa_link_7_collision">
      <origin rpy="0  0  0" xyz="0  0  0"/>
      <geometry>
        <mesh filename="meshes/link_7.stl" scale="1 1 1"/>
      </geometry>
    </collision>
    <visual name="lbr_iiwa_with_wsg50__lbr_iiwa_link_7_visual">
      <origin rpy="0  0  0" xyz="0  0  0"/>
      <geometry>
        <mesh filename="meshes/link_7.stl" scale="1 1 1"/>
      </geometry>
      <material name="Grey" />
    </visual>
  </link>
  <link name="lbr_iiwa_with_wsg50__base_link">
    <inertial>
      <mass value="0.2"/>
      <origin rpy="0  0  0" xyz="0  0  0"/>
      <inertia ixx="1" ixy="0" ixz="0" iyy="1" iyz="0" izz="1"/>
    </inertial>
    <collision name="lbr_iiwa_with_wsg50__base_link_collision">
      <origin rpy="0  0  0" xyz="0  0  0"/>
      <geometry>
        <box size="0.05 0.05 0.1"/>
      </geometry>
    </collision>
    <visual name="lbr_iiwa_with_wsg50__base_link_visual">
      <origin rpy="0  0  0" xyz="0  0  0"/>
      <geometry>
        <box size="0.05 0.05 0.1"/>
      </geometry>
      <material name="Grey" />
    </visual>
  </link>
  <link name="lbr_iiwa_with_wsg50__left_finger">
    <inertial>
      <mass value="0.2"/>
      <origin rpy="0  0  0" xyz="0    0    0.04"/>
      <inertia ixx="0.1" ixy="0" ixz="0" iyy="0.1" iyz="0" izz="0.1"/>
    </inertial>
    <collision name="lbr_iiwa_with_wsg50__left_finger_collision">
      <origin rpy="0  0  0" xyz="0    0    0.04"/>
      <geometry>
        <box size="0.01 0.01 0.08"/>
      </geometry>
    </collision>
    <visual name="lbr_iiwa_with_wsg50__left_finger_visual">
      <origin rpy="0  0  0" xyz="0    0    0.04"/>
      <geometry>
        <box size="0.01 0.01 0.08"/>
      </geometry>
      <material name="Grey" />
    </visual>
  </link>
  <link name="lbr_iiwa_with_wsg50__left_finger_base">
    <inertial>
      <mass value="0.2"/>
      <origin rpy="0  0  0" xyz="-0.003  0     0.04"/>
      <inertia ixx="0.1" ixy="0" ixz="0" iyy="0.1" iyz="0" izz="0.1"/>
    </inertial>
    <collision name="lbr_iiwa_with_wsg50__left_finger_base_collision">
      <origin rpy="0  0  0" xyz="0  0  0"/>
      <geometry>
        <mesh filename="meshes/finger_base_left.stl" scale="1 1 1"/>
      </geometry>
    </collision>
    <visual name="lbr_iiwa_with_wsg50__left_finger_base_visual">
      <origin rpy="0  0  0" xyz="0  0  0"/>
      <geometry>
        <mesh filename="meshes/finger_base_left.stl" scale="1 1 1"/>
      </geometry>
      <material name="Grey" />
    </visual>
  </link>
  <link name="lbr_iiwa_with_wsg50__left_finger_tip">
    <inertial>
      <mass value="0.2"/>
      <origin rpy="0  0  0" xyz="-0.005  0     0.026"/>
      <inertia ixx="0.1" ixy="0" ixz="0" iyy="0.1" iyz="0" izz="0.1"/>
    </inertial>
    <collision name="lbr_iiwa_with_wsg50__left_finger_tip_collision">
      <origin rpy="0  0  0" xyz="0  0  0"/>
      <geometry>
        <mesh filename="meshes/finger_tip_left.stl" scale="1 1 1"/>
      </geometry>
    </collision>
    <visual name="lbr_iiwa_with_wsg50__left_finger_tip_visual">
      <origin rpy="0  0  0" xyz="0  0  0"/>
      <geometry>
        <mesh filename="meshes/finger_tip_left.stl" scale="1 1 1"/>
      </geometry>
      <material name="Grey" />
    </visual>
  </link>
  <link name="lbr_iiwa_with_wsg50__right_finger">
    <inertial>
      <mass value="0.2"/>
      <origin rpy="0  0  0" xyz="0    0    0.04"/>
      <inertia ixx="0.1" ixy="0" ixz="0" iyy="0.1" iyz="0" izz="0.1"/>
    </inertial>
    <collision name="lbr_iiwa_with_wsg50__right_finger_collision">
      <origin rpy="0  0  0" xyz="0    0    0.04"/>
      <geometry>
        <box size="0.01 0.01 0.08"/>
      </geometry>
    </collision>
    <visual name="lbr_iiwa_with_wsg50__right_finger_visual">
      <origin rpy="0  0  0" xyz="0    0    0.04"/>
      <geometry>
        <box size="0.01 0.01 0.08"/>
      </geometry>
      <material name="Grey" />
    </visual>
  </link>
  <link name="lbr_iiwa_with_wsg50__right_finger_base">
    <inertial>
      <mass value="0.2"/>
      <origin rpy="0  0  0" xyz="0.003  0     0.04"/>
      <inertia ixx="0.1" ixy="0" ixz="0" iyy="0.1" iyz="0" izz="0.1"/>
    </inertial>
    <collision name="lbr_iiwa_with_wsg50__right_finger_base_collision">
      <origin rpy="0  0  0" xyz="0  0  0"/>
      <geometry>
        <mesh filename="meshes/finger_base_right.stl" scale="1 1 1"/>
      </geometry>
    </collision>
    <visual name="lbr_iiwa_with_wsg50__right_finger_base_visual">
      <origin rpy="0  0  0" xyz="0  0  0"/>
      <geometry>
        <mesh filename="meshes/finger_base_right.stl" scale="1 1 1"/>
      </geometry>
      <material name="Grey" />
    </visual>
  </link>
  <link name="lbr_iiwa_with_wsg50__right_finger_tip">
    <inertial>
      <mass value="0.2"/>
      <origin rpy="0  0  0" xyz="0.005  0     0.026"/>
      <inertia ixx="0.1" ixy="0" ixz="0" iyy="0.1" iyz="0" izz="0.1"/>
    </inertial>
    <collision name="lbr_iiwa_with_wsg50__right_finger_tip_collision">
      <origin rpy="0  0  0" xyz="0  0  0"/>
      <geometry>
        <mesh filename="meshes/finger_tip_right.stl" scale="1 1 1"/>
      </geometry>
    </collision>
    <visual name="lbr_iiwa_with_wsg50__right_finger_visual">
      <origin rpy="0  0  0" xyz="0  0  0"/>
      <geometry>
        <mesh filename="meshes/finger_tip_right.stl" scale="1 1 1"/>
      </geometry>
      <material name="Grey" />
    </visual>
  </link>
</robot>
